Workbook

Sheet TwoParticleOffset0
A1: P | B1: t | C1: iter | D1: vx | E1: vy | F1: pen_factor | G1: v_mag | H1: vel_mag_in | I1: v_coll | J1: v_ang | K1: ang_acc | L1: ang_diff | M1: imomx | N1: imomy | O1: imom | P1: tot_area | Q1: cur_area | R1: area_diff | S1: vx_rel | T1: vy_rel | U1: v_rel | V1: col_acc_x | W1: col_acc_y | X1: col_acc_mag | Y1: p_mom_x | Z1: p_mom_y | AA1: p_mom
A2: 0 | B2: 0.003 | C2: 1 | D2: 0.95 | E2: 0.05 | F2: 0 | G2: 0 | H2: 0 | I2: 0 | J2: 0 | K2: 0 | L2: 0 | M2: 0 | N2: 0 | O2: 0 | P2: 0 | Q2: 0 | R2: 0 | S2: 0 | T2: 0 | U2: 0 | V2: 0 | W2: 0 | X2: 0 | Y2: 0 | Z2: 0 | AA2: 0
A3: 0 | B3: 0.006 | C3: 2 | D3: 0.95 | E3: 0.05 | F3: 0 | G3: 0.95131488 | H3: 0 | I3: 0 | J3: 0.0526 | K3: 0 | L3: 0 | M3: 0 | N3: 0 | O3: 0 | P3: 0 | Q3: 0 | R3: 0 | S3: 0 | T3: 0 | U3: 0 | V3: 0 | W3: 0 | X3: 0 | Y3: 0 | Z3: 0 | AA3: 0
A4: 0 | B4: 0.009 | C4: 3 | D4: 0.95 | E4: 0.05 | F4: 0 | G4: 0.95131488 | H4: 0 | I4: 0 | J4: 0.0526 | K4: 0 | L4: 0 | M4: 0 | N4: 0 | O4: 0 | P4: 0 | Q4: 0 | R4: 0 | S4: 0 | T4: 0 | U4: 0 | V4: 0 | W4: 0 | X4: 0 | Y4: 0 | Z4: 0 | AA4: 0
A5: 0 | B5: 0.012 | C5: 4 | D5: 0.95 | E5: 0.05 | F5: 0 | G5: 0.95131488 | H5: 0 | I5: 0 | J5: 0.0526 | K5: 0 | L5: 0 | M5: 0 | N5: 0 | O5: 0 | P5: 0 | Q5: 0 | R5: 0 | S5: 0 | T5: 0 | U5: 0 | V5: 0 | W5: 0 | X5: 0 | Y5: 0 | Z5: 0 | AA5: 0
A6: 0 | B6: 0.015 | C6: 5 | D6: 0.95 | E6: 0.05 | F6: 0 | G6: 0.95131488 | H6: 0 | I6: 0 | J6: 0.0526 | K6: 0 | L6: 0 | M6: 0 | N6: 0 | O6: 0 | P6: 0 | Q6: 0 | R6: 0 | S6: 0 | T6: 0 | U6: 0 | V6: 0 | W6: 0 | X6: 0 | Y6: 0 | Z6: 0 | AA6: 0
A7: 0 | B7: 0.018 | C7: 6 | D7: 0.95 | E7: 0.05 | F7: 0 | G7: 0.95131488 | H7: 0 | I7: 0 | J7: 0.0526 | K7: 0 | L7: 0 | M7: 0 | N7: 0 | O7: 0 | P7: 0 | Q7: 0 | R7: 0 | S7: 0 | T7: 0 | U7: 0 | V7: 0 | W7: 0 | X7: 0 | Y7: 0 | Z7: 0 | AA7: 0
A8: 0 | B8: 0.021 | C8: 7 | D8: 0.95 | E8: 0.05 | F8: 0 | G8: 0.95131488 | H8: 0 | I8: 0 | J8: 0.0526 | K8: 0 | L8: 0 | M8: 0 | N8: 0 | O8: 0 | P8: 0 | Q8: 0 | R8: 0 | S8: 0 | T8: 0 | U8: 0 | V8: 0 | W8: 0 | X8: 0 | Y8: 0 | Z8: 0 | AA8: 0
A9: 0 | B9: 0.024 | C9: 8 | D9: 0.95 | E9: 0.05 | F9: 0 | G9: 0.95131488 | H9: 0 | I9: 0 | J9: 0.0526 | K9: 0 | L9: 0 | M9: 0 | N9: 0 | O9: 0 | P9: 0 | Q9: 0 | R9: 0 | S9: 0 | T9: 0 | U9: 0 | V9: 0 | W9: 0 | X9: 0 | Y9: 0 | Z9: 0 | AA9: 0
A10: 0 | B10: 0.027 | C10: 9 | D10: 0.95 | E10: 0.05 | F10: 0 | G10: 0.95131488 | H10: 0 | I10: 0 | J10: 0.0526 | K10: 0 | L10: 0 | M10: 0 | N10: 0 | O10: 0 | P10: 0 | Q10: 0 | R10: 0 | S10: 0 | T10: 0 | U10: 0 | V10: 0 | W10: 0 | X10: 0 | Y10: 0 | Z10: 0 | AA10: 0
A11: 0 | B11: 0.03 | C11: 10 | D11: 0.95 | E11: 0.05 | F11: 0 | G11: 0.95131488 | H11: 0 | I11: 0 | J11: 0.0526 | K11: 0 | L11: 0 | M11: 0 | N11: 0 | O11: 0 | P11: 0 | Q11: 0 | R11: 0 | S11: 0 | T11: 0 | U11: 0 | V11: 0 | W11: 0 | X11: 0 | Y11: 0 | Z11: 0 | AA11: 0
A12: 0 | B12: 0.033 | C12: 11 | D12: 0.95 | E12: 0.05 | F12: 0 | G12: 0.95131488 | H12: 0 | I12: 0 | J12: 0.0526 | K12: 0 | L12: 0 | M12: 0 | N12: 0 | O12: 0 | P12: 0 | Q12: 0 | R12: 0 | S12: 0 | T12: 0 | U12: 0 | V12: 0 | W12: 0 | X12: 0 | Y12: 0 | Z12: 0 | AA12: 0
A13: 0 | B13: 0.036 | C13: 12 | D13: 0.95 | E13: 0.05 | F13: 0 | G13: 0.95131488 | H13: 0 | I13: 0 | J13: 0.0526 | K13: 0 | L13: 0 | M13: 0 | N13: 0 | O13: 0 | P13: 0 | Q13: 0 | R13: 0 | S13: 0 | T13: 0 | U13: 0 | V13: 0 | W13: 0 | X13: 0 | Y13: 0 | Z13: 0 | AA13: 0
... A99: 0 | B99: 0.294 | C99: 98 | D99: 0.7776 | E99: 0.5793 | F99: 0 | G99: 0.96965736 | H99: 0.95131488 | I99: 0 | J99: 0.6403 | K99: 0 | L99: 0 | M99: 0 | N99: 0 | O99: 0 | P99: 0 | Q99: 0 | R99: 0 | S99: 0 | T99: 0 | U99: 0 | V99: 0 | W99: 0 | X99: 0 | Y99: 0 | Z99: 0 | AA99: 0

Sheet TwoParticleOffset1
A1: P | B1: t | C1: iter | D1: vx | E1: vy | F1: pen_factor | G1: v_mag | H1: vel_mag_in | I1: v_coll | J1: v_ang | K1: ang_acc | L1: ang_diff | M1: imomx | N1: imomy | O1: imom | P1: tot_area | Q1: cur_area | R1: area_diff | S1: vx_rel | T1: vy_rel | U1: v_rel | V1: col_acc_x | W1: col_acc_y | X1: col_acc_mag | Y1: p_mom_x | Z1: p_mom_y | AA1: p_mom
A2: 1 | B2: 0.003 | C2: 1 | D2: -1 | E2: 0 | F2: 0 | G2: 0 | H2: 0 | I2: 0 | J2: 0 | K2: 0 | L2: 0 | M2: 0 | N2: 0 | O2: 0 | P2: 0 | Q2: 0 | R2: 0 | S2: 0 | T2: 0 | U2: 0 | V2: 0 | W2: 0 | X2: 0 | Y2: 0 | Z2: 0 | AA2: 0
A3: 1 | B3: 0.006 | C3: 2 | D3: -1 | E3: 0 | F3: 0 | G3: 1 | H3: 0 | I3: 0 | J3: 3.1416 | K3: 0 | L3: 0 | M3: 0 | N3: 0 | O3: 0 | P3: 0 | Q3: 0 | R3: 0 | S3: 0 | T3: 0 | U3: 0 | V3: 0 | W3: 0 | X3: 0 | Y3: 0 | Z3: 0 | AA3: 0
A4: 1 | B4: 0.009 | C4: 3 | D4: -1 | E4: 0 | F4: 0 | G4: 1 | H4: 0 | I4: 0 | J4: 3.1416 | K4: 0 | L4: 0 | M4: 0 | N4: 0 | O4: 0 | P4: 0 | Q4: 0 | R4: 0 | S4: 0 | T4: 0 | U4: 0 | V4: 0 | W4: 0 | X4: 0 | Y4: 0 | Z4: 0 | AA4: 0
A5: 1 | B5: 0.012 | C5: 4 | D5: -1 | E5: 0 | F5: 0 | G5: 1 | H5: 0 | I5: 0 | J5: 3.1416 | K5: 0 | L5: 0 | M5: 0 | N5: 0 | O5: 0 | P5: 0 | Q5: 0 | R5: 0 | S5: 0 | T5: 0 | U5: 0 | V5: 0 | W5: 0 | X5: 0 | Y5: 0 | Z5: 0 | AA5: 0
A6: 1 | B6: 0.015 | C6: 5 | D6: -1 | E6: 0 | F6: 0 | G6: 1 | H6: 0 | I6: 0 | J6: 3.1416 | K6: 0 | L6: 0 | M6: 0 | N6: 0 | O6: 0 | P6: 0 | Q6: 0 | R6: 0 | S6: 0 | T6: 0 | U6: 0 | V6: 0 | W6: 0 | X6: 0 | Y6: 0 | Z6: 0 | AA6: 0
A7: 1 | B7: 0.018 | C7: 6 | D7: -1 | E7: 0 | F7: 0 | G7: 1 | H7: 0 | I7: 0 | J7: 3.1416 | K7: 0 | L7: 0 | M7: 0 | N7: 0 | O7: 0 | P7: 0 | Q7: 0 | R7: 0 | S7: 0 | T7: 0 | U7: 0 | V7: 0 | W7: 0 | X7: 0 | Y7: 0 | Z7: 0 | AA7: 0
A8: 1 | B8: 0.021 | C8: 7 | D8: -1 | E8: 0 | F8: 0 | G8: 1 | H8: 0 | I8: 0 | J8: 3.1416 | K8: 0 | L8: 0 | M8: 0 | N8: 0 | O8: 0 | P8: 0 | Q8: 0 | R8: 0 | S8: 0 | T8: 0 | U8: 0 | V8: 0 | W8: 0 | X8: 0 | Y8: 0 | Z8: 0 | AA8: 0
A9: 1 | B9: 0.024 | C9: 8 | D9: -1 | E9: 0 | F9: 0 | G9: 1 | H9: 0 | I9: 0 | J9: 3.1416 | K9: 0 | L9: 0 | M9: 0 | N9: 0 | O9: 0 | P9: 0 | Q9: 0 | R9: 0 | S9: 0 | T9: 0 | U9: 0 | V9: 0 | W9: 0 | X9: 0 | Y9: 0 | Z9: 0 | AA9: 0
A10: 1 | B10: 0.027 | C10: 9 | D10: -1 | E10: 0 | F10: 0 | G10: 1 | H10: 0 | I10: 0 | J10: 3.1416 | K10: 0 | L10: 0 | M10: 0 | N10: 0 | O10: 0 | P10: 0 | Q10: 0 | R10: 0 | S10: 0 | T10: 0 | U10: 0 | V10: 0 | W10: 0 | X10: 0 | Y10: 0 | Z10: 0 | AA10: 0
A11: 1 | B11: 0.03 | C11: 10 | D11: -1 | E11: 0 | F11: 0 | G11: 1 | H11: 0 | I11: 0 | J11: 3.1416 | K11: 0 | L11: 0 | M11: 0 | N11: 0 | O11: 0 | P11: 0 | Q11: 0 | R11: 0 | S11: 0 | T11: 0 | U11: 0 | V11: 0 | W11: 0 | X11: 0 | Y11: 0 | Z11: 0 | AA11: 0
A12: 1 | B12: 0.033 | C12: 11 | D12: -1 | E12: 0 | F12: 0 | G12: 1 | H12: 0 | I12: 0 | J12: 3.1416 | K12: 0 | L12: 0 | M12: 0 | N12: 0 | O12: 0 | P12: 0 | Q12: 0 | R12: 0 | S12: 0 | T12: 0 | U12: 0 | V12: 0 | W12: 0 | X12: 0 | Y12: 0 | Z12: 0 | AA12: 0
A13: 1 | B13: 0.036 | C13: 12 | D13: -1 | E13: 0 | F13: 0 | G13: 1 | H13: 0 | I13: 0 | J13: 3.1416 | K13: 0 | L13: 0 | M13: 0 | N13: 0 | O13: 0 | P13: 0 | Q13: 0 | R13: 0 | S13: 0 | T13: 0 | U13: 0 | V13: 0 | W13: 0 | X13: 0 | Y13: 0 | Z13: 0 | AA13: 0
... A99: 1 | B99: 0.294 | C99: 98 | D99: -0.8276 | E99: -0.5293 | F99: 0 | G99: 0.98237163 | H99: 1 | I99: 0 | J99: 3.7106 | K99: 0 | L99: 0 | M99: 0 | N99: 0 | O99: 0 | P99: 0 | Q99: 0 | R99: 0 | S99: 0 | T99: 0 | U99: 0 | V99: 0 | W99: 0 | X99: 0 | Y99: 0 | Z99: 0 | AA99: 0

Sheet Vals
A1: Radius | B1: =PI()*0.25^2 -> 0.19634954 | H1: P1 Area Change | J1: P1 Area Cgnage
B2: 1 | C2: 2 | H2: =TwoParticleOffset0!L22 -> -0.00970247 | J2: =TwoParticleOffset1!R20 -> -2.062e-05
A3: Starting Momentum | B3: =TwoParticleOffset0!G19 -> 0.95131488 | C3: =TwoParticleOffset1!G20 -> 1 | D3: =SUM(B3:C3) -> 1.9513149 | H3: =TwoParticleOffset0!L23 -> -0.00983194 | I3: =H2-H3 -> 0.00012947 | J3: =TwoParticleOffset1!R21 -> -0.00016684 | K3: =J2-J3 -> 0.00014622
A4: Ending Momentum | B4: =TwoParticleOffset0!G78 -> 0.96965736 | C4: =TwoParticleOffset1!G78 -> 0.98237163 | D4: =SUM(B4:C4) -> 1.952029 | H4: =TwoParticleOffset0!L24 -> -0.00996193 | I4: =H3-H4 -> 0.00012999 | J4: =TwoParticleOffset1!R22 -> -0.00024946 | K4: =J3-J4 -> 8.262e-05
A5: Diff | B5: =B4-B3 -> 0.01834248 | C5: =C4-C3 -> -0.01762837 | D5: =D4-D3 -> 0.00071411 | E5: =D5/2 -> 0.000357055 | H5: =TwoParticleOffset0!L25 -> -0.01009221 | I5: =H4-H5 -> 0.00013028 | J5: =TwoParticleOffset1!R23 -> -0.00030516 | K5: =J4-J5 -> 5.57e-05
A6: Remaining Mom | H6: =TwoParticleOffset0!L26 -> -0.01022252 | I6: =H5-H6 -> 0.00013031 | J6: =TwoParticleOffset1!R24 -> -0.00034743 | K6: =J5-J6 -> 4.227e-05
A7: Pmom | B7: =TwoParticleOffset0!AA76 -> 0.96951118 | C7: =TwoParticleOffset1!AA76 -> 0.98223984 | D7: =B7+C7 -> 1.951751
A8: Pmom Diff | B8: =B4-B7 -> 0.00014618 | C8: =C4-C7 -> 0.00013179 | D8: =B8+C8 -> 0.00027797
A10: Area | B10: =PI()*0.25^2 -> 0.19634954 | H10: =TwoParticleOffset0!L27 -> -0.01035254 | I10: =H6-H10 -> 0.00013002 | J10: =TwoParticleOffset1!R25 -> -0.0003806 | K10: =J6-J10 -> 3.317e-05
A11: Sum Area | B11: =SUM(TwoParticleOffset0!M20:M49) -> -0.1231 | C11: =SUM(TwoParticleOffset1!M20:M49) -> 0.1231 | D11: =SUM(B11:C11) -> 0 | E11: =D11-B10 -> -0.19634954 | H11: =TwoParticleOffset0!L28 -> -0.01048194 | I11: =H10-H11 -> 0.0001294 | J11: =TwoParticleOffset1!R26 -> -0.00040669 | K11: =J10-J11 -> 2.609e-05
A12: Sum Area Diff | B12: =SUM(TwoParticleOffset0!N19:N49) -> 0.2777 | C12: =SUM(TwoParticleOffset1!N20:N49) -> -0.2777 | D12: =SUM(B12:C12) -> 0 | H12: =TwoParticleOffset0!L29 -> -0.01061034 | I12: =H11-H12 -> 0.0001284 | J12: =TwoParticleOffset1!R27 -> -0.00042685 | K12: =J11-J12 -> 2.016e-05
A13: Momentum Per area | B13: =B10/B3 -> 0.20639805 | C13: =B10/C3 -> 0.19634954 | H13: =TwoParticleOffset0!L30 -> -0.01073734 | I13: =H12-H13 -> 0.000127 | J13: =TwoParticleOffset1!R28 -> -0.00044179 | K13: =J12-J13 -> 1.494e-05
A14: Remaing Area*momper | B14: =B13*B12 -> 0.05731674 | C14: =C13*C12 -> -0.054526267 | H14: =TwoParticleOffset0!L31 -> -0.01086251 | I14: =H13-H14 -> 0.00012517 | J14: =TwoParticleOffset1!R29 -> -0.00045196 | K14: =J13-J14 -> 1.017e-05
A15: imom | B15: =TwoParticleOffset0!H49 -> 0.95131488 | C15: =TwoParticleOffset1!H49 -> 1 | D15: =SUM(B15:C15) -> 1.9513149 | H15: =TwoParticleOffset0!L32 -> -0.01098538 | I15: =H14-H15 -> 0.00012287 | J15: =TwoParticleOffset1!R30 -> -0.0004577 | K15: =J14-J15 -> 5.74e-06
H16: =TwoParticleOffset0!L33 -> -0.01110549 | I16: =H15-H16 -> 0.00012011 | J16: =TwoParticleOffset1!R31 -> -0.00045925 | K16: =J15-J16 -> 1.55e-06
A17: Total Angle Change | B17: =SUM(TwoParticleOffset0!L22:L76) -> -0.62059865 | H17: =TwoParticleOffset0!L34 -> -0.01122232 | I17: =H16-H17 -> 0.00011683 | J17: =TwoParticleOffset1!R32 -> -0.00045683 | K17: =J16-J17 -> -2.42e-06
A18: Second Derive Area Change Sum | B18: =SUM(I3:I59) -> 0.00017188 | C18: =SUM(K3:K60) -> -0.00034078 | D18: =B18+C18 -> -0.0001689 | H18: =TwoParticleOffset0!L35 -> -0.01133537 | I18: =H17-H18 -> 0.00011305 | J18: =TwoParticleOffset1!R33 -> -0.0004506 | K18: =J17-J18 -> -6.23e-06
A19: Times V_rel | B19: =D3*B18 -> 0.000335392 | C19: =D3*C18 -> -0.00066496908 | D19: =B19+C19 -> -0.00032957708 | H19: =TwoParticleOffset0!L36 -> -0.01144411 | I19: =H18-H19 -> 0.00010874 | J19: =TwoParticleOffset1!R34 -> -0.00044074 | K19: =J18-J19 -> -9.86e-06
H20: =TwoParticleOffset0!L37 -> -0.01154801 | I20: =H19-H20 -> 0.0001039 | J20: =TwoParticleOffset1!R35 -> -0.0004274 | K20: =J19-J20 -> -1.334e-05
H21: =TwoParticleOffset0!L38 -> -0.01164656 | I21: =H20-H21 -> 9.855e-05 | J21: =TwoParticleOffset1!R36 -> -0.00041074 | K21: =J20-J21 -> -1.666e-05
H22: =TwoParticleOffset0!L39 -> -0.01173922 | I22: =H21-H22 -> 9.266e-05 | J22: =TwoParticleOffset1!R37 -> -0.00039094 | K22: =J21-J22 -> -1.98e-05
H23: =TwoParticleOffset0!L40 -> -0.0118255 | I23: =H22-H23 -> 8.628e-05 | J23: =TwoParticleOffset1!R38 -> -0.00036818 | K23: =J22-J23 -> -2.276e-05
H24: =TwoParticleOffset0!L41 -> -0.01190489 | I24: =H23-H24 -> 7.939e-05 | J24: =TwoParticleOffset1!R39 -> -0.00034265 | K24: =J23-J24 -> -2.553e-05
H25: =TwoParticleOffset0!L42 -> -0.01197695 | I25: =H24-H25 -> 7.206e-05 | J25: =TwoParticleOffset1!R40 -> -0.00031456 | K25: =J24-J25 -> -2.809e-05
H26: =TwoParticleOffset0!L43 -> -0.01204123 | I26: =H25-H26 -> 6.428e-05 | J26: =TwoParticleOffset1!R41 -> -0.00028412 | K26: =J25-J26 -> -3.044e-05
H27: =TwoParticleOffset0!L44 -> -0.01209735 | I27: =H26-H27 -> 5.612e-05 | J27: =TwoParticleOffset1!R42 -> -0.00025157 | K27: =J26-J27 -> -3.255e-05
H28: =TwoParticleOffset0!L45 -> -0.01214494 | I28: =H27-H28 -> 4.759e-05 | J28: =TwoParticleOffset1!R43 -> -0.00021716 | K28: =J27-J28 -> -3.441e-05
H29: =TwoParticleOffset0!L46 -> -0.01218372 | I29: =H28-H29 -> 3.878e-05 | J29: =TwoParticleOffset1!R44 -> -0.00018114 | K29: =J28-J29 -> -3.602e-05
H30: =TwoParticleOffset0!L47 -> -0.01221342 | I30: =H29-H30 -> 2.97e-05 | J30: =TwoParticleOffset1!R45 -> -0.00014377 | K30: =J29-J30 -> -3.737e-05
H31: =TwoParticleOffset0!L48 -> -0.01223385 | I31: =H30-H31 -> 2.043e-05 | J31: =TwoParticleOffset1!R46 -> -0.00010535 | K31: =J30-J31 -> -3.842e-05
... H59: =TwoParticleOffset0!L76 -> -0.00987435 | I59: =H58-H59 -> -0.00013012 | J59: =TwoParticleOffset1!R74 -> 0.00032016 | K59: =J58-J59 -> 3.898e-05
H60: =TwoParticleOffset0!L77 -> 0
H61: =TwoParticleOffset0!L78 -> 0
H62: =TwoParticleOffset0!L79 -> 0
H63: =TwoParticleOffset0!L80 -> 0
H64: =TwoParticleOffset0!L81 -> 0
H65: =TwoParticleOffset0!#REF! -> #REF!
H66: =TwoParticleOffset0!L99 -> 0
H67: =TwoParticleOffset0!L100 -> 0
H68: =TwoParticleOffset0!L101 -> 0
...

Sheet PregMom
A1: v_mag | B1: p_mag | C1: diff | D1: SumDiff
A2: =TwoParticleOffset0C0[[#This Row],[v_mag]] -> 0
A3: =TwoParticleOffset0C0[[#This Row],[v_mag]] -> 0.95131488 | D3: =SUM(C3:C48) -> -0.32639249
A4: =TwoParticleOffset0C0[[#This Row],[v_mag]] -> 0.95131488
A5: =TwoParticleOffset0C0[[#This Row],[v_mag]] -> 0.95131488
A6: =TwoParticleOffset0C0[[#This Row],[v_mag]] -> 0.95131488
A7: =TwoParticleOffset0C0[[#This Row],[v_mag]] -> 0.95131488
A8: =TwoParticleOffset0C0[[#This Row],[v_mag]] -> 0.95131488
A9: =TwoParticleOffset0C0[[#This Row],[v_mag]] -> 0.95131488
A10: =TwoParticleOffset0C0[[#This Row],[v_mag]] -> 0.95131488
A11: =TwoParticleOffset0C0[[#This Row],[v_mag]] -> 0.95131488
A12: =TwoParticleOffset0C0[[#This Row],[v_mag]] -> 0.95131488
A13: =TwoParticleOffset0C0[[#This Row],[v_mag]] -> 0.95131488
A14: =TwoParticleOffset0C0[[#This Row],[v_mag]] -> 0.95131488
A15: =TwoParticleOffset0C0[[#This Row],[v_mag]] -> 0.95131488
... A20: =TwoParticleOffset0C0[[#This Row],[v_mag]] -> 0.95131488
A21: =TwoParticleOffset0C0[[#This Row],[v_mag]] -> 0.95129286 | B21: =TwoParticleOffset0!AA49 -> 0.8883662 | C21: =A21-B21 -> 0.06292666
A22: =TwoParticleOffset0C0[[#This Row],[v_mag]] -> 0.95109576 | B22: =TwoParticleOffset0!AA50 -> 0.88945529 | C22: =A22-B22 -> 0.06164047
A23: =TwoParticleOffset0C0[[#This Row],[v_mag]] -> 0.95064384 | B23: =TwoParticleOffset0!AA51 -> 0.89109006 | C23: =A23-B23 -> 0.05955378
A24: =TwoParticleOffset0C0[[#This Row],[v_mag]] -> 0.94988982 | B24: =TwoParticleOffset0!AA52 -> 0.89324801 | C24: =A24-B24 -> 0.05664181
A25: =TwoParticleOffset0C0[[#This Row],[v_mag]] -> 0.94880408 | B25: =TwoParticleOffset0!AA53 -> 0.89589733 | C25: =A25-B25 -> 0.05290675
A26: =TwoParticleOffset0C0[[#This Row],[v_mag]] -> 0.94736997 | B26: =TwoParticleOffset0!AA54 -> 0.89899768 | C26: =A26-B26 -> 0.04837229
A27: =TwoParticleOffset0C0[[#This Row],[v_mag]] -> 0.94558162 | B27: =TwoParticleOffset0!AA55 -> 0.90250118 | C27: =A27-B27 -> 0.04308044
A28: =TwoParticleOffset0C0[[#This Row],[v_mag]] -> 0.94344267 | B28: =TwoParticleOffset0!AA56 -> 0.90635364 | C28: =A28-B28 -> 0.03708903
A29: =TwoParticleOffset0C0[[#This Row],[v_mag]] -> 0.9409655 | B29: =TwoParticleOffset0!AA57 -> 0.91049577 | C29: =A29-B29 -> 0.03046973
A30: =TwoParticleOffset0C0[[#This Row],[v_mag]] -> 0.93817062 | B30: =TwoParticleOffset0!AA58 -> 0.9148646 | C30: =A30-B30 -> 0.02330602
A31: =TwoParticleOffset0C0[[#This Row],[v_mag]] -> 0.93508615 | B31: =TwoParticleOffset0!AA59 -> 0.91939475 | C31: =A31-B31 -> 0.0156914
A32: =TwoParticleOffset0C0[[#This Row],[v_mag]] -> 0.93174729 | B32: =TwoParticleOffset0!AA60 -> 0.92401987 | C32: =A32-B32 -> 0.00772742
... A48: =TwoParticleOffset0C0[[#This Row],[v_mag]] -> 0.88783535 | B48: =TwoParticleOffset0!AA76 -> 0.96951118 | C48: =A48-B48 -> -0.08167583
A49: =TwoParticleOffset0C0[[#This Row],[v_mag]] -> 0.8883662 | B49: =TwoParticleOffset0!AA77 -> 0
A50: =TwoParticleOffset0C0[[#This Row],[v_mag]] -> 0.88945529 | B50: =TwoParticleOffset0!AA78 -> 0
A51: =TwoParticleOffset0C0[[#This Row],[v_mag]] -> 0.89109006 | B51: =TwoParticleOffset0!AA79 -> 0
A52: =TwoParticleOffset0C0[[#This Row],[v_mag]] -> 0.89324801 | B52: =TwoParticleOffset0!AA80 -> 0
A53: =TwoParticleOffset0C0[[#This Row],[v_mag]] -> 0.89589733 | B53: =TwoParticleOffset0!AA81 -> 0
A54: =TwoParticleOffset0C0[[#This Row],[v_mag]] -> 0.89899768 | B54: =TwoParticleOffset0!AA82 -> 0
A55: =TwoParticleOffset0C0[[#This Row],[v_mag]] -> 0.90250118 | B55: =TwoParticleOffset0!#REF! -> #REF!
A56: =TwoParticleOffset0C0[[#This Row],[v_mag]] -> 0.90635364 | B56: =TwoParticleOffset0!#REF! -> #REF!
A57: =TwoParticleOffset0C0[[#This Row],[v_mag]] -> 0.91049577 | B57: =TwoParticleOffset0!#REF! -> #REF!
A58: =TwoParticleOffset0C0[[#This Row],[v_mag]] -> 0.9148646 | B58: =TwoParticleOffset0!#REF! -> #REF!
A59: =TwoParticleOffset0C0[[#This Row],[v_mag]] -> 0.91939475 | B59: =TwoParticleOffset0!#REF! -> #REF!
...
